Необходимые переменные окружения доступны.
отправляем api-запрос
Сбой в работе программы: Авторизация не пройдена {'Authorization': 'OAuth AQAAAAABOp_LAAYckT-HtaroxEwAtVw-ygQCrts'}, 
Эндпоинт https://practicum.yandex.ru/api/user_api/homework_statuses/, текущее время 1653048648.8455043, 
Проблемы соединения с сервером, 
ошибка 400
Traceback (most recent call last):
  File "homework.py", line 151, in main
    response = get_api_answer(current_timestamp)
  File "homework.py", line 87, in get_api_answer
    raise TypeError(error_message)
TypeError: Авторизация не пройдена {'Authorization': 'OAuth AQAAAAABOp_LAAYckT-HtaroxEwAtVw-ygQCrts'}, 
Эндпоинт https://practicum.yandex.ru/api/user_api/homework_statuses/, текущее время 1653048648.8455043, 
Проблемы соединения с сервером, 
ошибка 400
Авторизация не пройдена {'Authorization': 'OAuth AQAAAAABOp_LAAYckT-HtaroxEwAtVw-ygQCrts'}, 
Эндпоинт https://practicum.yandex.ru/api/user_api/homework_statuses/, текущее время 1653048648.8455043, 
Проблемы соединения с сервером, 
ошибка 400
Необходимые переменные окружения доступны.
отправляем api-запрос
Сбой в работе программы: Авторизация не пройдена {'Authorization': 'OAuth AQAAAAABOp_LAAYckT-HtaroxEwAtVw-ygQCrts'}, 
Эндпоинт https://practicum.yandex.ru/api/user_api/homework_statuses/, текущее время 1653048712.408707, 
Проблемы соединения с сервером, 
ошибка 400
Traceback (most recent call last):
  File "homework.py", line 151, in main
    response = get_api_answer(current_timestamp)
  File "homework.py", line 87, in get_api_answer
    raise TypeError(error_message)
TypeError: Авторизация не пройдена {'Authorization': 'OAuth AQAAAAABOp_LAAYckT-HtaroxEwAtVw-ygQCrts'}, 
Эндпоинт https://practicum.yandex.ru/api/user_api/homework_statuses/, текущее время 1653048712.408707, 
Проблемы соединения с сервером, 
ошибка 400
Авторизация не пройдена {'Authorization': 'OAuth AQAAAAABOp_LAAYckT-HtaroxEwAtVw-ygQCrts'}, 
Эндпоинт https://practicum.yandex.ru/api/user_api/homework_statuses/, текущее время 1653048712.408707, 
Проблемы соединения с сервером, 
ошибка 400
Необходимые переменные окружения доступны.
отправляем api-запрос
Сбой в работе программы: Авторизация не пройдена {'Authorization': 'OAuth AQAAAAABOp_LAAYckT-HtaroxEwAtVw-ygQCrts'}, 
Эндпоинт https://practicum.yandex.ru/api/user_api/homework_statuses/, текущее время 1653048829.47876, 
Проблемы соединения с сервером, 
ошибка 400
Traceback (most recent call last):
  File "homework.py", line 151, in main
    response = get_api_answer(current_timestamp)
  File "homework.py", line 87, in get_api_answer
    raise TypeError(error_message)
TypeError: Авторизация не пройдена {'Authorization': 'OAuth AQAAAAABOp_LAAYckT-HtaroxEwAtVw-ygQCrts'}, 
Эндпоинт https://practicum.yandex.ru/api/user_api/homework_statuses/, текущее время 1653048829.47876, 
Проблемы соединения с сервером, 
ошибка 400
Авторизация не пройдена {'Authorization': 'OAuth AQAAAAABOp_LAAYckT-HtaroxEwAtVw-ygQCrts'}, 
Эндпоинт https://practicum.yandex.ru/api/user_api/homework_statuses/, текущее время 1653048829.47876, 
Проблемы соединения с сервером, 
ошибка 400
